<mujoco model="hospital">
  <option timestep="0.005" integrator="RK4"/>

  <visual>
    <headlight diffuse="0.6 0.6 0.6" ambient="0.3 0.3 0.3" specular="0 0 0"/>
    <rgba haze="0.15 0.25 0.35 1"/>
    <global azimuth="120" elevation="-20"/>
  </visual>

  <default>
    <geom rgba=".8 .9 .9 1"/>
    <default class="wall">
      <geom rgba=".7 .7 .7 1"/>
    </default>
  </default>

  <asset>
    <texture type="skybox" builtin="gradient" rgb1="0.9 0.95 1" rgb2="0.6 0.8 1" width="256" height="256"/>
    <texture name="floor_tex" type="2d" builtin="checker" rgb1=".9 .9 .9" rgb2=".8 .8 .8" width="512" height="512" mark="edge" markrgb=".5 .5 .5"/>
    <texture name="wood_tex" type="cube" builtin="flat" rgb1=".5 .4 .3" width="100" height="100"/>
    <texture name="metal_tex" type="cube" builtin="flat" rgb1=".8 .8 .8" width="100" height="100"/>
    
    <material name="floor_mat" texture="floor_tex" texrepeat="5 5" specular="0.1" shininess="0.2"/>
    <material name="wall_mat" rgba=".92 .96 .94 1" specular="0.1" shininess="0.1"/>
    <material name="wood_mat" texture="wood_tex" specular="0.2" shininess="0.3"/>
    <material name="metal_mat" texture="metal_tex" specular="0.8" shininess="0.8"/>
  </asset>

  <worldbody>
    <!-- 光源 -->
    <!-- 主环境光（暖色） -->
    <light pos="0 5 5" dir="0 -1 -1" diffuse="1 0.98 0.95" castshadow="false"/>
    <!-- 补光（冷色） -->
    <light pos="5 0 5" dir="-1 0 -1" diffuse="0.8 0.85 0.9" castshadow="false"/>
    <light pos="-5 0 5" dir="1 0 -1" diffuse="0.8 0.85 0.9" castshadow="false"/>
    <!-- 顶光 -->
    <light pos="0 0 5" dir="0 0 -1" diffuse="0.6 0.6 0.6" castshadow="false"/>
    <!-- 检查灯（聚光灯效果，照向病床） -->
    <light pos="-2 0 4" dir="0 0 -1" diffuse="0.8 0.8 0.7" castshadow="true" cutoff="45"/>

    <!-- 地面 -->
    <geom type="plane" size="10 10 0.1" material="floor_mat"/>
    
    <!-- 墙壁 -->
    <geom type="box" size="5 0.1 3" pos="0 -5 1.5" material="wall_mat"/>
    <geom type="box" size="5 0.1 3" pos="0 5 1.5" material="wall_mat"/>
    <geom type="box" size="0.1 5 3" pos="-5 0 1.5" material="wall_mat"/>
    <geom type="box" size="0.1 5 3" pos="5 0 1.5" material="wall_mat"/>
    
    <!-- 墙面防撞条 -->
    <geom type="box" size="5 0.02 0.1" pos="0 -4.9 1" material="wood_mat"/>
    <geom type="box" size="5 0.02 0.1" pos="0 4.9 1" material="wood_mat"/>
    <geom type="box" size="0.02 5 0.1" pos="-4.9 0 1" material="wood_mat"/>
    <geom type="box" size="0.02 5 0.1" pos="4.9 0 1" material="wood_mat"/>

    <!-- 挂钟 -->
    <body pos="0 4.9 3.5">
       <geom type="cylinder" size="0.2 0.02" axis="0 1 0" rgba="1 1 1 1"/>
       <geom type="cylinder" size="0.22 0.02" axis="0 1 0" pos="0 0.01 0" rgba=".2 .2 .2 1"/>
       <!-- 指针 -->
       <geom type="capsule" size="0.01" fromto="0 0.03 0  0 0.03 0.15" rgba="0 0 0 1"/>
       <geom type="capsule" size="0.01" fromto="0 0.03 0  0.1 0.03 0" rgba="0 0 0 1"/>
    </body>

    <!-- 医用白板/图表 -->
    <body pos="-4.9 0 2.5">
       <geom type="box" size="0.02 0.6 0.4" rgba="1 1 1 1"/>
       <geom type="box" size="0.01 0.62 0.42" pos="-0.01 0 0" rgba=".8 .8 .8 1"/>
       <!-- 简单的图表线条 -->
       <geom type="capsule" size="0.005" fromto="0.03 -0.4 0.2  0.03 0.4 -0.2" rgba="0 0 1 1"/>
       <geom type="capsule" size="0.005" fromto="0.03 -0.4 -0.2  0.03 0.4 0.2" rgba="1 0 0 1"/>
    </body>

    <!-- 踢脚线 -->
    <geom type="box" size="5 0.12 0.1" pos="0 -5 0.1" material="metal_mat" rgba=".4 .4 .4 1"/>
    <geom type="box" size="5 0.12 0.1" pos="0 5 0.1" material="metal_mat" rgba=".4 .4 .4 1"/>
    <geom type="box" size="0.12 5 0.1" pos="-5 0 0.1" material="metal_mat" rgba=".4 .4 .4 1"/>
    <geom type="box" size="0.12 5 0.1" pos="5 0 0.1" material="metal_mat" rgba=".4 .4 .4 1"/>
    <!-- 门 -->
    <geom type="box" size="0.1 1 2" pos="5 0 1" material="wood_mat" rgba=".6 .4 .3 1"/>
    <!-- 门框 -->
    <geom type="box" size="0.15 0.1 2" pos="5 1.1 1" material="wood_mat" rgba=".3 .2 .1 1"/>
    <geom type="box" size="0.15 0.1 2" pos="5 -1.1 1" material="wood_mat" rgba=".3 .2 .1 1"/>
    <geom type="box" size="0.15 1.2 0.1" pos="5 0 2.1" material="wood_mat" rgba=".3 .2 .1 1"/>
    <!-- 窗户 -->
    <geom type="box" size="1 0.1 1.5" pos="0 4.9 1.25" rgba=".4 .6 .8 0.5"/>
    <geom type="box" size="0.1 0.5 1.5" pos="-0.5 4.9 1.25" material="metal_mat" rgba=".6 .6 .6 1"/>
    <geom type="box" size="1 0.1 0.1" pos="0 4.9 0.5" material="metal_mat" rgba=".6 .6 .6 1"/>
    <geom type="box" size="1 0.1 0.1" pos="0 4.9 2" material="metal_mat" rgba=".6 .6 .6 1"/>
    
    <!-- 隔帘轨道 -->
    <geom type="capsule" size="0.02" fromto="-3.5 -1.5 2.8  -0.5 -1.5 2.8" material="metal_mat" rgba=".8 .8 .8 1"/>
    <geom type="capsule" size="0.02" fromto="-0.5 -1.5 2.8  -0.5 1.5 2.8" material="metal_mat" rgba=".8 .8 .8 1"/>
    <geom type="capsule" size="0.02" fromto="-0.5 1.5 2.8  -3.5 1.5 2.8" material="metal_mat" rgba=".8 .8 .8 1"/>
    <!-- 隔帘（收起状态） -->
    <geom type="cylinder" size="0.15 1" pos="-3.4 -1.4 1.8" rgba=".4 .6 .6 1"/>

    <!-- 病床（精细化模型） -->
    <body pos="-2 0 0.5">
      <!-- 床架 -->
      <geom type="box" size="1.2 0.6 0.1" rgba=".7 .7 .7 1"/>
      <geom type="box" size="0.1 0.6 0.4" pos="-0.55 0 0.2" rgba=".7 .7 .7 1"/>
      <geom type="box" size="0.1 0.6 0.4" pos="0.55 0 0.2" rgba=".7 .7 .7 1"/>
      <geom type="box" size="1.2 0.1 0.4" pos="0 -0.25 0.2" rgba=".7 .7 .7 1"/>
      <geom type="box" size="1.2 0.1 0.4" pos="0 0.25 0.2" rgba=".7 .7 .7 1"/>
      <!-- 床垫 -->
      <geom type="box" size="1.1 0.5 0.05" pos="0 0 0.55" rgba=".9 0.85 0.8 1"/>
      <!-- 枕头 -->
      <geom type="box" size="0.3 0.4 0.05" pos="-0.45 0 0.6" rgba=".95 0.9 0.85 1"/>
      <!-- 床单 -->
      <geom type="box" size="1.15 0.55 0.02" pos="0 0 0.62" rgba="0.95 0.95 0.98 0.8"/>
      <!-- 左侧护栏 -->
      <geom type="cylinder" size="0.02 0.4" pos="-0.4 0.3 0.75" material="metal_mat" rgba=".6 .6 .6 1"/>
      <geom type="cylinder" size="0.02 0.4" pos="0 0.3 0.75" material="metal_mat" rgba=".6 .6 .6 1"/>
      <geom type="cylinder" size="0.02 0.4" pos="0.4 0.3 0.75" material="metal_mat" rgba=".6 .6 .6 1"/>
      <geom type="box" size="0.35 0.02 0.15" pos="-0.4 0.3 0.95" material="metal_mat" rgba=".6 .6 .6 1"/>
      <geom type="box" size="0.35 0.02 0.15" pos="0 0.3 0.95" material="metal_mat" rgba=".6 .6 .6 1"/>
      <geom type="box" size="0.35 0.02 0.15" pos="0.4 0.3 0.95" material="metal_mat" rgba=".6 .6 .6 1"/>
      <!-- 右侧护栏 -->
      <geom type="cylinder" size="0.02 0.4" pos="-0.4 -0.3 0.75" material="metal_mat" rgba=".6 .6 .6 1"/>
      <geom type="cylinder" size="0.02 0.4" pos="0 -0.3 0.75" material="metal_mat" rgba=".6 .6 .6 1"/>
      <geom type="cylinder" size="0.02 0.4" pos="0.4 -0.3 0.75" material="metal_mat" rgba=".6 .6 .6 1"/>
      <geom type="box" size="0.35 0.02 0.15" pos="-0.4 -0.3 0.95" material="metal_mat" rgba=".6 .6 .6 1"/>
      <geom type="box" size="0.35 0.02 0.15" pos="0 -0.3 0.95" material="metal_mat" rgba=".6 .6 .6 1"/>
      <geom type="box" size="0.35 0.02 0.15" pos="0.4 -0.3 0.95" material="metal_mat" rgba=".6 .6 .6 1"/>
      <!-- 床头板 -->
      <geom type="box" size="0.05 0.6 0.6" pos="-0.6 0 0.3" rgba=".5 .4 .3 1"/>
      <!-- 床尾板 -->
      <geom type="box" size="0.05 0.6 0.6" pos="0.6 0 0.3" rgba=".5 .4 .3 1"/>
      <!-- 脚轮 -->
      <geom type="cylinder" size="0.05 0.03" pos="-0.5 0.25 0.015" rgba=".3 .3 .3 1"/>
      <geom type="cylinder" size="0.05 0.03" pos="-0.5 -0.25 0.015" rgba=".3 .3 .3 1"/>
      <geom type="cylinder" size="0.05 0.03" pos="0.5 0.25 0.015" rgba=".3 .3 .3 1"/>
      <geom type="cylinder" size="0.05 0.03" pos="0.5 -0.25 0.015" rgba=".3 .3 .3 1"/>
      <!-- 角度调节手柄 -->
      <geom type="cylinder" size="0.03 0.15" pos="0.55 0.15 0.1" rgba=".4 .4 .4 1"/>
      <geom type="box" size="0.02 0.1 0.02" pos="0.55 0.25 0.1" rgba=".3 .3 .3 1"/>
      <!-- 病历卡夹 -->
      <geom type="box" size="0.02 0.15 0.2" pos="0.66 0 0.3" rgba=".9 .9 .9 1"/>
      <geom type="box" size="0.01 0.12 0.15" pos="0.67 0 0.3" rgba="1 1 1 1"/>
    </body>

    <!-- 床头柜 -->
    <body pos="-2 -1 0.5">
      <geom type="box" size="0.4 0.4 0.4" material="wood_mat" rgba=".7 .5 .3 1"/>
      <geom type="box" size="0.35 0.35 0.05" pos="0 0 0.8" material="wood_mat" rgba=".8 .6 .4 1"/>
      <!-- 抽屉 -->
      <geom type="box" size="0.3 0.3 0.1" pos="0 0 0.4" material="wood_mat" rgba=".75 .6 .45 1"/>
      <geom type="box" size="0.3 0.3 0.1" pos="0 0 0.2" material="wood_mat" rgba=".75 .6 .45 1"/>
      <!-- 物品 -->
      <geom type="cylinder" size="0.05 0.1" pos="0.1 0 0.85" rgba=".9 .9 .1 1"/>
      <geom type="box" size="0.1 0.1 0.1" pos="-0.1 0 0.85" rgba=".2 .4 .8 1"/>
    </body>

    <!-- 输液架 -->
    <body pos="-1.5 -0.5 0">
      <geom type="cylinder" size="0.03 1.5" pos="0 0 0.75" material="metal_mat" rgba=".7 .7 .7 1"/>
      <geom type="cylinder" size="0.02 0.5" pos="0.3 0 1.5" material="metal_mat" rgba=".7 .7 .7 1"/>
      <geom type="sphere" size="0.08" pos="0.3 0 1.75" rgba=".2 .4 .8 1"/>
      <geom type="cylinder" size="0.01 0.5" pos="0.3 0 1.3" rgba=".2 .4 .8 0.5"/>
    </body>

    <!-- 氧气罐 -->
    <body pos="-3 -1 0">
      <geom type="cylinder" size="0.2 0.5" pos="0 0 0.25" rgba=".2 .4 .8 1"/>
      <geom type="cylinder" size="0.15 0.1" pos="0 0 0.6" rgba=".7 .7 .7 1"/>
      <geom type="box" size="0.1 0.1 0.1" pos="0 0 0.7" rgba=".7 .7 .7 1"/>
    </body>

    <!-- 医疗设备 -->
    <body pos="2 0 1">
      <!-- 设备主体 -->
      <geom type="box" size="0.5 0.5 0.8" rgba=".6 .8 .9 1"/>
      <!-- 显示屏支架 -->
      <geom type="cylinder" size="0.05 0.3" pos="0.2 0 1.2" rgba=".5 .5 .5 1"/>
      <!-- 显示屏 -->
      <geom type="box" size="0.3 0.3 0.1" pos="0.2 0 1.4" rgba=".9 .9 .9 1"/>
      <geom type="box" size="0.25 0.25 0.01" pos="0.2 0 1.45" rgba=".1 .1 .1 1"/>
      <!-- 控制面板 -->
      <geom type="box" size="0.3 0.3 0.05" pos="0 0 1.6" rgba=".8 .8 .8 1"/>
      <!-- 按钮 -->
      <geom type="sphere" size="0.02" pos="-0.1 0.1 1.63" rgba=".2 .8 .2 1"/>
      <geom type="sphere" size="0.02" pos="0 0.1 1.63" rgba=".8 .2 .2 1"/>
      <geom type="sphere" size="0.02" pos="0.1 0.1 1.63" rgba=".2 .2 .8 1"/>
      <geom type="sphere" size="0.02" pos="-0.1 0 1.63" rgba=".8 .8 .2 1"/>
      <geom type="sphere" size="0.02" pos="0 0 1.63" rgba=".8 .2 .8 1"/>
      <geom type="sphere" size="0.02" pos="0.1 0 1.63" rgba=".2 .8 .8 1"/>
      <!-- 连接线 -->
      <geom type="capsule" size="0.01" fromto="0.2 0 1.45  0.1 0 1.58" rgba=".2 .2 .2 1"/>
    </body>

    <!-- 医疗推车 -->
    <body pos="3 -2 0.5">
      <!-- 推车主体 -->
      <geom type="box" size="0.6 0.6 0.4" material="metal_mat" rgba=".7 .7 .7 1"/>
      <!--把手-->
      <geom type="capsule" size="0.02" fromto="-0.3 -0.65 0.5  0.3 -0.65 0.5" material="metal_mat" rgba=".4 .4 .4 1"/>
      <geom type="capsule" size="0.02" fromto="-0.3 -0.65 0.5  -0.3 -0.3 0.3" material="metal_mat" rgba=".4 .4 .4 1"/>
      <geom type="capsule" size="0.02" fromto="0.3 -0.65 0.5  0.3 -0.3 0.3" material="metal_mat" rgba=".4 .4 .4 1"/>
      <!-- 轮子 -->
      <geom type="cylinder" size="0.08 0.02" pos="0.2 0.2 0.02" rgba=".3 .3 .3 1"/>
      <geom type="cylinder" size="0.08 0.02" pos="0.2 -0.2 0.02" rgba=".3 .3 .3 1"/>
      <geom type="cylinder" size="0.08 0.02" pos="-0.2 0.2 0.02" rgba=".3 .3 .3 1"/>
      <geom type="cylinder" size="0.08 0.02" pos="-0.2 -0.2 0.02" rgba=".3 .3 .3 1"/>
      <!-- 托盘 -->
      <geom type="box" size="0.5 0.5 0.05" pos="0 0 0.8" material="metal_mat" rgba=".8 .8 .8 1"/>
      <!-- 物品 -->
      <geom type="box" size="0.15 0.15 0.15" pos="0.15 0.15 0.85" rgba=".8 .2 .2 1"/>
      <geom type="box" size="0.1 0.1 0.1" pos="-0.15 0.15 0.85" rgba=".2 .8 .2 1"/>
      <geom type="cylinder" size="0.05 0.1" pos="0 -0.15 0.85" rgba=".2 .4 .8 1"/>
    </body>



    <!-- 桌子 -->
    <body pos="0 -2 0.5">
      <geom type="box" size="0.6 0.6 0.4" material="wood_mat" rgba=".7 .5 .3 1"/>
      <geom type="box" size="0.1 0.1 0.4" pos="0.25 0.25 0.2" material="wood_mat" rgba=".7 .5 .3 1"/>
      <geom type="box" size="0.1 0.1 0.4" pos="0.25 -0.25 0.2" material="wood_mat" rgba=".7 .5 .3 1"/>
      <geom type="box" size="0.1 0.1 0.4" pos="-0.25 0.25 0.2" material="wood_mat" rgba=".7 .5 .3 1"/>
      <geom type="box" size="0.1 0.1 0.4" pos="-0.25 -0.25 0.2" material="wood_mat" rgba=".7 .5 .3 1"/>
      <geom type="box" size="0.4 0.4 0.05" pos="0 0 0.8" material="wood_mat" rgba=".8 .6 .4 1"/>
      <!-- 物品 -->
      <geom type="box" size="0.15 0.15 0.02" pos="0 0 0.83" rgba=".9 .9 .9 1"/>
      <geom type="cylinder" size="0.04 0.08" pos="0.1 0.1 0.85" rgba=".7 .7 .7 1"/>
    </body>

    <!-- 椅子（改进模型） -->
    <body pos="1 -2 0.5">
      <geom type="box" size="0.3 0.3 0.4" rgba=".5 .7 .5 1"/>
      <geom type="box" size="0.05 0.05 0.4" pos="0.1 0.1 0.2" rgba=".5 .7 .5 1"/>
      <geom type="box" size="0.05 0.05 0.4" pos="0.1 -0.1 0.2" rgba=".5 .7 .5 1"/>
      <geom type="box" size="0.05 0.05 0.4" pos="-0.1 0.1 0.2" rgba=".5 .7 .5 1"/>
      <geom type="box" size="0.05 0.05 0.4" pos="-0.1 -0.1 0.2" rgba=".5 .7 .5 1"/>
      <!-- 座位 -->
      <geom type="box" size="0.2 0.2 0.05" pos="0 0 0.8" rgba=".6 .8 .6 1"/>
      <!-- 靠背 -->
      <geom type="box" size="0.05 0.15 0.2" pos="0 0.1 0.6" rgba=".5 .7 .5 1"/>
    </body>

    <!-- 洗手盆 -->
    <body pos="4 3 0.5">
      <geom type="cylinder" size="0.3 0.1" pos="0 0 0.4" rgba=".9 .9 .9 1"/>
      <geom type="cylinder" size="0.25 0.1" pos="0 0 0.55" rgba=".8 .8 .8 1"/>
      <geom type="cylinder" size="0.15 0.1" pos="0 0 0.6" rgba=".7 .7 .7 1"/>
      <geom type="box" size="0.05 0.05 0.4" pos="0.15 0 0.2" material="metal_mat" rgba=".6 .6 .6 1"/>
      <!-- 水龙头 -->
      <geom type="cylinder" size="0.02 0.1" pos="0.1 0 0.75" material="metal_mat" rgba=".5 .5 .5 1"/>
      <geom type="cylinder" size="0.03 0.05" pos="0.1 0 0.85" material="metal_mat" rgba=".4 .4 .4 1"/>
      <geom type="cylinder" size="0.02 0.08" pos="0.1 0.05 0.88" material="metal_mat" rgba=".4 .4 .4 1"/>
      <geom type="sphere" size="0.02" pos="0.1 0.13 0.88" material="metal_mat" rgba=".3 .3 .3 1"/>
    </body>

    <!-- 医疗柜 -->
    <body pos="4 1 1">
      <geom type="box" size="0.8 0.4 1.2" material="metal_mat" rgba=".9 .9 .9 1"/>
      <geom type="box" size="0.75 0.35 0.5" pos="0 0 0.35" rgba=".85 .85 .85 1"/>
      <geom type="box" size="0.75 0.35 0.5" pos="0 0 -0.35" rgba=".85 .85 .85 1"/>
      <!-- 柜门把手 -->
      <geom type="cylinder" size="0.02 0.05" pos="0.2 0.18 0.35" material="metal_mat" rgba=".5 .5 .5 1"/>
      <geom type="cylinder" size="0.02 0.05" pos="0.2 0.18 -0.35" material="metal_mat" rgba=".5 .5 .5 1"/>
      <!-- 药品瓶 -->
      <geom type="cylinder" size="0.05 0.1" pos="-0.2 0 0.45" rgba=".2 .6 .2 0.8"/>
      <geom type="cylinder" size="0.04 0.08" pos="0 0 0.45" rgba=".8 .2 .2 0.8"/>
      <geom type="cylinder" size="0.05 0.12" pos="0.2 0 0.45" rgba=".2 .2 .8 0.8"/>
    </body>

    <!-- 除颤仪 -->
    <body pos="3 2 0.5">
      <geom type="box" size="0.4 0.3 0.2" rgba=".2 .2 .2 1"/>
      <geom type="box" size="0.35 0.25 0.05" pos="0 0 0.1" rgba=".8 .8 .8 1"/>
      <!-- 屏幕 -->
      <geom type="box" size="0.25 0.15 0.02" pos="0 0 0.13" rgba=".2 .3 .4 1"/>
      <!-- 除颤电极板 -->
      <geom type="cylinder" size="0.08 0.03" pos="-0.15 0 0.22" rgba=".4 .4 .4 1"/>
      <geom type="cylinder" size="0.08 0.03" pos="0.15 0 0.22" rgba=".4 .4 .4 1"/>
      <geom type="cylinder" size="0.02 0.2" pos="-0.15 0 0.18" rgba=".3 .3 .3 1"/>
      <geom type="cylinder" size="0.02 0.2" pos="0.15 0 0.18" rgba=".3 .3 .3 1"/>
      <!-- 握把 -->
      <geom type="box" size="0.02 0.15 0.02" pos="-0.15 0 0.25" rgba=".5 .5 .5 1"/>
      <geom type="box" size="0.02 0.15 0.02" pos="0.15 0 0.25" rgba=".5 .5 .5 1"/>
      <!-- 警示灯 -->
      <geom type="sphere" size="0.03" pos="0 0.1 0.12" rgba=".8 .2 .2 1"/>
      <!-- 脚轮 -->
      <geom type="cylinder" size="0.04 0.02" pos="0.12 0.1 0.01" rgba=".3 .3 .3 1"/>
      <geom type="cylinder" size="0.04 0.02" pos="0.12 -0.1 0.01" rgba=".3 .3 .3 1"/>
      <geom type="cylinder" size="0.04 0.02" pos="-0.12 0.1 0.01" rgba=".3 .3 .3 1"/>
      <geom type="cylinder" size="0.04 0.02" pos="-0.12 -0.1 0.01" rgba=".3 .3 .3 1"/>
    </body>

    <!-- 呼吸机 -->
    <body pos="1 4 0.5">
      <geom type="box" size="0.3 0.3 0.4" rgba=".9 .9 .9 1"/>
      <!-- 显示屏 -->
      <geom type="box" size="0.2 0.15 0.02" pos="0 0 0.22" rgba=".1 .1 .1 1"/>
      <geom type="box" size="0.18 0.13 0.01" pos="0 0 0.24" rgba=".2 .5 .2 0.9"/>
      <!-- 湿化器 -->
      <geom type="cylinder" size="0.08 0.1" pos="0 0 0.4" rgba=".6 .6 .8 1"/>
      <geom type="cylinder" size="0.06 0.08" pos="0 0 0.52" rgba=".7 .7 .9 0.8"/>
      <!-- 管路 -->
      <geom type="cylinder" size="0.03 0.3" pos="0.15 0 0.55" rgba=".6 .6 .6 0.6"/>
      <!-- 面罩 -->
      <geom type="sphere" size="0.06" pos="0.3 0 0.55" rgba=".5 .5 .5 0.7"/>
      <!-- 支架 -->
      <geom type="cylinder" size="0.02 0.5" pos="-0.12 0 0.25" rgba=".4 .4 .4 1"/>
      <geom type="cylinder" size="0.02 0.4" pos="0.12 0 0.25" rgba=".4 .4 .4 1"/>
    </body>

    <!-- 墙面呼叫器 -->
    <body pos="-3.5 4.95 1.2">
      <geom type="box" size="0.1 0.02 0.15" rgba=".9 .9 .9 1"/>
      <geom type="box" size="0.08 0.01 0.08" pos="0 0.01 0.03" rgba=".2 .8 .2 1"/>
      <geom type="box" size="0.08 0.01 0.03" pos="0 0.01 -0.04" rgba=".8 .2 .2 1"/>
    </body>

    <!-- 墙面指示牌 -->
    <body pos="2 4.95 2">
      <geom type="box" size="0.3 0.02 0.15" rgba=".2 .6 .8 1"/>
      <geom type="box" size="0.25 0.01 0.1" pos="0 0.01 0" rgba=".95 .95 .95 0.9"/>
    </body>

    <!-- 药品推车 -->
    <body pos="3 4 0.5">
      <geom type="box" size="0.5 0.3 0.6" rgba=".7 .7 .8 1"/>
      <!-- 抽屉 -->
      <geom type="box" size="0.45 0.25 0.1" pos="0 0 0.25" rgba=".75 .75 .85 1"/>
      <geom type="box" size="0.45 0.25 0.1" pos="0 0 0.1" rgba=".75 .75 .85 1"/>
      <geom type="box" size="0.45 0.25 0.1" pos="0 0 -0.05" rgba=".75 .75 .85 1"/>
      <!-- 抽屉把手 -->
      <geom type="box" size="0.08 0.02 0.02" pos="0 0.13 0.25" rgba=".5 .5 .5 1"/>
      <geom type="box" size="0.08 0.02 0.02" pos="0 0.13 0.1" rgba=".5 .5 .5 1"/>
      <geom type="box" size="0.08 0.02 0.02" pos="0 0.13 -0.05" rgba=".5 .5 .5 1"/>
      <!-- 托盘 -->
      <geom type="box" size="0.4 0.25 0.02" pos="0 0 0.6" rgba=".8 .8 .9 1"/>
      <!-- 药品盒 -->
      <geom type="box" size="0.1 0.15 0.08" pos="-0.1 0 0.63" rgba=".2 .6 .2 1"/>
      <geom type="box" size="0.08 0.12 0.06" pos="0.05 0 0.63" rgba=".8 .2 .2 1"/>
      <geom type="box" size="0.12 0.1 0.07" pos="0.15 -0.05 0.63" rgba=".2 .2 .8 1"/>
      <!-- 轮子 -->
      <geom type="cylinder" size="0.05 0.02" pos="0.15 0.12 0.01" rgba=".3 .3 .3 1"/>
      <geom type="cylinder" size="0.05 0.02" pos="0.15 -0.12 0.01" rgba=".3 .3 .3 1"/>
      <geom type="cylinder" size="0.05 0.02" pos="-0.15 0.12 0.01" rgba=".3 .3 .3 1"/>
      <geom type="cylinder" size="0.05 0.02" pos="-0.15 -0.12 0.01" rgba=".3 .3 .3 1"/>
      <!-- 手柄 -->
      <geom type="cylinder" size="0.02 0.15" pos="0 0.15 0.35" rgba=".4 .4 .4 1"/>
      <geom type="box" size="0.02 0.08 0.02" pos="0 0.19 0.35" rgba=".3 .3 .3 1"/>
    </body>

    <!-- 改进的护士模型 -->
    <body pos="-1 2 1.5">
      <joint type="ball"/>
      <!-- 头部 -->
      <geom type="sphere" size="0.15" pos="0 0 0" rgba=".8 .6 .4 1"/>
      <!-- 眼睛 -->
      <geom type="sphere" size="0.015" pos="0.05 -0.13 0.02" rgba="0 0 0 1"/>
      <geom type="sphere" size="0.015" pos="-0.05 -0.13 0.02" rgba="0 0 0 1"/>
      <!-- 护士帽 -->
      <geom type="cylinder" size="0.16 0.05" pos="0 0 0.08" rgba=".95 .95 .95 1"/>
      <geom type="box" size="0.12 0.01 0.1" pos="0 0 0.12" rgba=".95 .95 .95 1"/>
      <!-- 躯干 -->
      <geom type="capsule" size="0.15" fromto="0 0 -0.1  0 0 -0.5" rgba=".6 .2 .2 1"/>
      <body pos="0 0 -0.5">
        <joint axis="0 1 0"/>
        <joint axis="1 0 0"/>
        <!-- 左手 -->
        <geom type="capsule" size="0.06" fromto="0 0 0  0.25 0 0" rgba=".8 .6 .4 1"/>
        <geom type="sphere" size="0.07" pos="0.3 0 0" rgba=".8 .6 .4 1"/>
        <!-- 右手 -->
        <geom type="capsule" size="0.06" fromto="0 0 0  -0.25 0 0" rgba=".8 .6 .4 1"/>
        <geom type="sphere" size="0.07" pos="-0.3 0 0" rgba=".8 .6 .4 1"/>
        <!-- 左手臂 -->
        <geom type="capsule" size="0.08" fromto="0.25 0 0  0.4 0.15 0" rgba=".6 .2 .2 1"/>
        <!-- 右手臂 -->
        <geom type="capsule" size="0.08" fromto="-0.25 0 0  -0.4 0.15 0" rgba=".6 .2 .2 1"/>
        <!-- 腿 -->
        <geom type="capsule" size="0.1" fromto="0 0 0  0 0.3 0" rgba=".6 .2 .2 1"/>
        <geom type="capsule" size="0.1" fromto="0 0 0  0 -0.3 0" rgba=".6 .2 .2 1"/>
        <!-- 鞋子 -->
        <geom type="box" size="0.08 0.12 0.04" pos="0 0.36 0" rgba=".3 .3 .3 1"/>
        <geom type="box" size="0.08 0.12 0.04" pos="0 -0.36 0" rgba=".3 .3 .3 1"/>
      </body>
    </body>

    <!-- 改进的患者模型（平躺） -->
    <body pos="-2 0 1.25">
      <joint type="free"/>
      <!-- 头部 -->
      <geom type="sphere" size="0.15" pos="-0.4 0 0" rgba=".8 .6 .4 1"/>
      <!-- 眼睛 -->
      <geom type="sphere" size="0.015" pos="-0.35 0.05 0.12" rgba="0 0 0 1"/>
      <geom type="sphere" size="0.015" pos="-0.35 -0.05 0.12" rgba="0 0 0 1"/>
      <!-- 头发 -->
      <geom type="sphere" size="0.14" pos="-0.45 0 -0.02" rgba=".3 .3 .3 0.5"/>
      <!-- 躯干 -->
      <geom type="capsule" size="0.15" fromto="-0.3 0 0  0.3 0 0" rgba=".2 .4 .8 1"/>
      <!-- 左手 -->
      <geom type="capsule" size="0.06" fromto="-0.2 0.2 0  0.2 0.25 0" rgba=".8 .6 .4 1"/>
      <geom type="sphere" size="0.07" pos="0.25 0.25 0" rgba=".8 .6 .4 1"/>
      <!-- 右手 -->
      <geom type="capsule" size="0.06" fromto="-0.2 -0.2 0  0.2 -0.25 0" rgba=".8 .6 .4 1"/>
      <geom type="sphere" size="0.07" pos="0.25 -0.25 0" rgba=".8 .6 .4 1"/>
      <!-- 腿 -->
      <geom type="capsule" size="0.1" fromto="0.3 0 0  0.8 0.1 0" rgba=".2 .4 .8 1"/>
      <geom type="capsule" size="0.1" fromto="0.3 0 0  0.8 -0.1 0" rgba=".2 .4 .8 1"/>
      <!-- 脚 -->
      <geom type="box" size="0.05 0.08 0.12" pos="0.85 0.1 0.05" rgba=".8 .6 .4 1"/>
      <geom type="box" size="0.05 0.08 0.12" pos="0.85 -0.1 0.05" rgba=".8 .6 .4 1"/>
      <!-- 病号服细节 -->
      <geom type="capsule" size="0.08" fromto="-0.1 0.2 0.05  0.1 0.22 0.05" rgba=".9 .9 .9 0.8"/>
      <geom type="capsule" size="0.08" fromto="-0.1 -0.2 0.05  0.1 -0.22 0.05" rgba=".9 .9 .9 0.8"/>
    </body>

    <!-- 医生模型 -->
    <body pos="0 3 1.6">
      <joint type="ball"/>
      <!-- 头部 -->
      <geom type="sphere" size="0.16" pos="0 0 0" rgba=".8 .6 .4 1"/>
      <!-- 眼睛 -->
      <geom type="sphere" size="0.015" pos="0.06 -0.14 0.03" rgba="0 0 0 1"/>
      <geom type="sphere" size="0.015" pos="-0.06 -0.14 0.03" rgba="0 0 0 1"/>
      <!-- 听诊器挂耳部 -->
      <geom type="sphere" size="0.04" pos="0.12 0.06 0.05" rgba=".3 .3 .3 1"/>
      <geom type="sphere" size="0.04" pos="-0.12 0.06 0.05" rgba=".3 .3 .3 1"/>
      <!-- 躯干 -->
      <geom type="capsule" size="0.17" fromto="0 0 -0.1  0 0 -0.55" rgba=".95 .95 .95 1"/>
      <!-- 白大褂下摆 -->
      <geom type="capsule" size="0.18" fromto="0 0 -0.45  0 0 -0.7" rgba=".9 .9 .9 1"/>
      <body pos="0 0 -0.55">
        <joint axis="0 1 0"/>
        <joint axis="1 0 0"/>
        <!-- 左手 -->
        <geom type="capsule" size="0.07" fromto="0 0 0  0.3 0 0" rgba=".8 .6 .4 1"/>
        <geom type="sphere" size="0.08" pos="0.35 0 0" rgba=".8 .6 .4 1"/>
        <!-- 右手 -->
        <geom type="capsule" size="0.07" fromto="0 0 0  -0.3 0 0" rgba=".8 .6 .4 1"/>
        <geom type="sphere" size="0.08" pos="-0.35 0 0" rgba=".8 .6 .4 1"/>
        <!-- 听诊器 -->
        <geom type="sphere" size="0.05" pos="0.25 0 -0.1" rgba=".3 .3 .3 1"/>
        <geom type="cylinder" size="0.01 0.15" pos="0.15 0 -0.15" rgba=".3 .3 .3 1"/>
        <!-- 腿 -->
        <geom type="capsule" size="0.11" fromto="0 0 0  0 0.35 0" rgba=".3 .3 .35 1"/>
        <geom type="capsule" size="0.11" fromto="0 0 0  0 -0.35 0" rgba=".3 .3 .35 1"/>
        <!-- 鞋子 -->
        <geom type="box" size="0.1 0.14 0.05" pos="0 0.4 0" rgba=".2 .2 .2 1"/>
        <geom type="box" size="0.1 0.14 0.05" pos="0 -0.4 0" rgba=".2 .2 .2 1"/>
      </body>
    </body>
  </worldbody>
</mujoco>